Workbook
Name Category: Lookup_Tables!$B$2:$B$7
Name Category: Cleaned_Data!$H$2:$H$1001
Name Category_Fetched: Cleaned_Data!$G$2:$G$1001
Name Cost: Lookup_Tables!$C$2:$C$7
Name Cost_Price: Cleaned_Data!$M$2:$M$1001
Name Discount: Cleaned_Data!$K$2:$K$1001
Name Discount_Fixed: Cleaned_Data!$L$2:$L$1001
Name Order_Date: Cleaned_Data!$B$2:$B$1001
Name Order_ID: Cleaned_Data!$A$2:$A$1001
Name Product: Lookup_Tables!$A$2:$A$7
Name Product: Cleaned_Data!$F$2:$F$1001
Name Quantity: Cleaned_Data!$I$2:$I$1001
Name Region: Lookup_Tables!$A$10:$A$13
Name Region: Cleaned_Data!$C$2:$C$1001
Name Salesperson: Cleaned_Data!$E$2:$E$1001
Name Slicer_Category_Fetched: #N/A
Name Slicer_Region: #N/A
Name Slicer_Salesperson: #N/A
Name State: Cleaned_Data!$D$2:$D$1001
Name Target: Lookup_Tables!$B$10:$B$13
Name Unit_Price: Cleaned_Data!$J$2:$J$1001

Sheet Pivot_Region
A3: Region | B3: Sum of Net Sales | C3: Sum of Profit
A4: West | B4: 35441355 | C4: 14659572
A5: East | B5: 34750454 | C5: 14298080
A6: South | B6: 33255425 | C6: 13234378
A7: North | B7: 31196598 | C7: 12740410
A8: Grand Total | B8: 1.3464383e+08 | C8: 54932439
B9: =GETPIVOTDATA("Sum of Net Sales",$A$3) -> 1.3464383e+08 | C9: =GETPIVOTDATA("Sum of Profit",$A$3) -> 54932439
A12: Profit Margin | B12: =C9/B9 -> 0.40798334

Sheet Pivot_Monthly
A3: Row Labels | B3: Sum of Net Sales
A4: 2024 | B4: 1.3464383e+08
A5: Jan | B5: 12049850
A6: Feb | B6: 11624511
A7: Mar | B7: 11738510
A8: Apr | B8: 11563072
A9: May | B9: 12858819
A10: Jun | B10: 10720336
A11: Jul | B11: 9789583.2
A12: Aug | B12: 10397072
A13: Sep | B13: 8724617.5
A14: Oct | B14: 11253295
A15: Nov | B15: 12412820
... A17: Grand Total | B17: 1.3464383e+08

Sheet Pivot_Top_Products
A3: Row Labels | B3: Sum of Net Sales
A4: Laptop | B4: 24677543
A5: Desk | B5: 23970747
A6: Mouse | B6: 23393985
A7: Printer | B7: 23082613
A8: Monitor | B8: 21632257
A9: Grand Total | B9: 1.1675715e+08

Sheet Pivot_Salesperson
A3: Row Labels | B3: Sum of Profit | C3: Sum of Net Sales
A4: Rahul | B4: 11643235 | C4: 27582502
A5: Amit | B5: 11354836 | C5: 27419885
A6: Karan | B6: 11317797 | C6: 26856380
A7: Neha | B7: 10250730 | C7: 26655418
A8: Priya | B8: 10365842 | C8: 26129647
A9: Grand Total | B9: 54932439 | C9: 1.3464383e+08

Sheet Dashboard
F13: =

Sheet Cleaned_Data
A1: Order ID | B1: Order Date | C1: Region | D1: State | E1: Salesperson | F1: Product | G1: Category_Fetched | H1: Category | I1: Quantity | J1: Unit Price | K1: Discount | L1: Discount_Fixed | M1: Cost Price | N1: Total Sales | O1: Net Sales | P1: Total Cost | Q1: Profit | R1: Profit Margin
A2: ORD0001 | B2: 45503 | C2: East | D2: MH | E2: Rahul | F2: Chair | G2: =INDEX(Lookup_Tables!$B$1:$B$7,MATCH(Cleaned_Data!F2,Lookup_Tables!$A$1:$A$7,0)) -> Furniture | H2: Furniture | I2: 8 | J2: 25761 | K2: 0.05 | L2: =IF(ISBLANK(K2),0,K2) -> 0.05 | M2: 29955 | N2: =I2*J2 -> 206088 | O2: =N2-(N2*L2) -> 195783.6 | P2: =I2*IFERROR(_xlfn.XLOOKUP(F2,Lookup_Tables!Product,Cost),0) -> 106168 | Q2: =O2-P2 -> 89615.6 | R2: =Q2/O2 -> 0.45772782
A3: ORD0002 | B3: 45527 | C3: West | D3: RJ | E3: Neha | F3: Laptop | G3: =INDEX(Lookup_Tables!$B$1:$B$7,MATCH(Cleaned_Data!F3,Lookup_Tables!$A$1:$A$7,0)) -> Electronics | H3: Electronics | I3: 3 | J3: 21400 | L3: =IF(ISBLANK(K3),0,K3) -> 0 | M3: 6742 | N3: =I3*J3 -> 64200 | O3: =N3-(N3*L3) -> 64200 | P3: =I3*IFERROR(_xlfn.XLOOKUP(F3,Lookup_Tables!Product,Cost),0) -> 57795 | Q3: =O3-P3 -> 6405 | R3: =Q3/O3 -> 0.099766355
A4: ORD0003 | B4: 45624 | C4: East | D4: GJ | E4: Karan | F4: Laptop | G4: =INDEX(Lookup_Tables!$B$1:$B$7,MATCH(Cleaned_Data!F4,Lookup_Tables!$A$1:$A$7,0)) -> Electronics | H4: Electronics | I4: 6 | J4: 40298 | L4: =IF(ISBLANK(K4),0,K4) -> 0 | N4: =I4*J4 -> 241788 | O4: =N4-(N4*L4) -> 241788 | P4: =I4*IFERROR(_xlfn.XLOOKUP(F4,Lookup_Tables!Product,Cost),0) -> 115590 | Q4: =O4-P4 -> 126198 | R4: =Q4/O4 -> 0.52193657
A5: ORD0004 | B5: 45311 | C5: North | D5: MH | E5: Rahul | F5: Monitor | G5: =INDEX(Lookup_Tables!$B$1:$B$7,MATCH(Cleaned_Data!F5,Lookup_Tables!$A$1:$A$7,0)) -> Electronics | H5: Electronics | I5: 9 | J5: 1098 | L5: =IF(ISBLANK(K5),0,K5) -> 0 | M5: 7334 | N5: =I5*J5 -> 9882 | O5: =N5-(N5*L5) -> 9882 | P5: =I5*IFERROR(_xlfn.XLOOKUP(F5,Lookup_Tables!Product,Cost),0) -> 25992 | Q5: =O5-P5 -> -16110 | R5: =Q5/O5 -> -1.6302368
A6: ORD0005 | B6: 45632 | C6: West | D6: RJ | E6: Karan | F6: Chair | G6: =INDEX(Lookup_Tables!$B$1:$B$7,MATCH(Cleaned_Data!F6,Lookup_Tables!$A$1:$A$7,0)) -> Furniture | H6: Furniture | I6: 4 | J6: 15968 | L6: =IF(ISBLANK(K6),0,K6) -> 0 | N6: =I6*J6 -> 63872 | O6: =N6-(N6*L6) -> 63872 | P6: =I6*IFERROR(_xlfn.XLOOKUP(F6,Lookup_Tables!Product,Cost),0) -> 53084 | Q6: =O6-P6 -> 10788 | R6: =Q6/O6 -> 0.1689003
A7: ORD0006 | B7: 45339 | C7: West | D7: RJ | E7: Amit | F7: Printer | G7: =INDEX(Lookup_Tables!$B$1:$B$7,MATCH(Cleaned_Data!F7,Lookup_Tables!$A$1:$A$7,0)) -> Electronics | H7: Electronics | I7: 10 | J7: 36961 | K7: 0.05 | L7: =IF(ISBLANK(K7),0,K7) -> 0.05 | M7: 16608 | N7: =I7*J7 -> 369610 | O7: =N7-(N7*L7) -> 351129.5 | P7: =I7*IFERROR(_xlfn.XLOOKUP(F7,Lookup_Tables!Product,Cost),0) -> 73840 | Q7: =O7-P7 -> 277289.5 | R7: =Q7/O7 -> 0.78970722
A8: ORD0007 | B8: 45618 | C8: North | D8: MH | E8: Amit | F8: Monitor | G8: =INDEX(Lookup_Tables!$B$1:$B$7,MATCH(Cleaned_Data!F8,Lookup_Tables!$A$1:$A$7,0)) -> Electronics | H8: Electronics | I8: 3 | J8: 1683 | L8: =IF(ISBLANK(K8),0,K8) -> 0 | M8: 25507 | N8: =I8*J8 -> 5049 | O8: =N8-(N8*L8) -> 5049 | P8: =I8*IFERROR(_xlfn.XLOOKUP(F8,Lookup_Tables!Product,Cost),0) -> 8664 | Q8: =O8-P8 -> -3615 | R8: =Q8/O8 -> -0.71598336
A9: ORD0008 | B9: 45476 | C9: South | D9: KA | E9: Amit | F9: Printer | G9: =INDEX(Lookup_Tables!$B$1:$B$7,MATCH(Cleaned_Data!F9,Lookup_Tables!$A$1:$A$7,0)) -> Electronics | H9: Electronics | I9: 2 | J9: 6047 | K9: 0.05 | L9: =IF(ISBLANK(K9),0,K9) -> 0.05 | N9: =I9*J9 -> 12094 | O9: =N9-(N9*L9) -> 11489.3 | P9: =I9*IFERROR(_xlfn.XLOOKUP(F9,Lookup_Tables!Product,Cost),0) -> 14768 | Q9: =O9-P9 -> -3278.7 | R9: =Q9/O9 -> -0.28536987
A10: ORD0009 | B10: 45530 | C10: North | D10: MH | E10: Amit | F10: Mouse | G10: =INDEX(Lookup_Tables!$B$1:$B$7,MATCH(Cleaned_Data!F10,Lookup_Tables!$A$1:$A$7,0)) -> Electronics | H10: Electronics | I10: 2 | J10: 3101 | K10: 0.1 | L10: =IF(ISBLANK(K10),0,K10) -> 0.1 | M10: 23538 | N10: =I10*J10 -> 6202 | O10: =N10-(N10*L10) -> 5581.8 | P10: =I10*IFERROR(_xlfn.XLOOKUP(F10,Lookup_Tables!Product,Cost),0) -> 56092 | Q10: =O10-P10 -> -50510.2 | R10: =Q10/O10 -> -9.0490881
A11: ORD0010 | B11: 45413 | C11: West | D11: MH | E11: Neha | F11: Printer | G11: =INDEX(Lookup_Tables!$B$1:$B$7,MATCH(Cleaned_Data!F11,Lookup_Tables!$A$1:$A$7,0)) -> Electronics | H11: Electronics | I11: 8 | J11: 41602 | K11: 0 | L11: =IF(ISBLANK(K11),0,K11) -> 0 | M11: 29885 | N11: =I11*J11 -> 332816 | O11: =N11-(N11*L11) -> 332816 | P11: =I11*IFERROR(_xlfn.XLOOKUP(F11,Lookup_Tables!Product,Cost),0) -> 59072 | Q11: =O11-P11 -> 273744 | R11: =Q11/O11 -> 0.82250853
A12: ORD0011 | B12: 45649 | C12: West | D12: GJ | E12: Karan | F12: Laptop | G12: =INDEX(Lookup_Tables!$B$1:$B$7,MATCH(Cleaned_Data!F12,Lookup_Tables!$A$1:$A$7,0)) -> Electronics | H12: Electronics | I12: 2 | J12: 17931 | K12: 0.1 | L12: =IF(ISBLANK(K12),0,K12) -> 0.1 | N12: =I12*J12 -> 35862 | O12: =N12-(N12*L12) -> 32275.8 | P12: =I12*IFERROR(_xlfn.XLOOKUP(F12,Lookup_Tables!Product,Cost),0) -> 38530 | Q12: =O12-P12 -> -6254.2 | R12: =Q12/O12 -> -0.19377366
A13: ORD0012 | B13: 45443 | C13: West | D13: TN | E13: Rahul | F13: Printer | G13: =INDEX(Lookup_Tables!$B$1:$B$7,MATCH(Cleaned_Data!F13,Lookup_Tables!$A$1:$A$7,0)) -> Electronics | H13: Electronics | I13: 3 | J13: 571 | K13: 0.1 | L13: =IF(ISBLANK(K13),0,K13) -> 0.1 | N13: =I13*J13 -> 1713 | O13: =N13-(N13*L13) -> 1541.7 | P13: =I13*IFERROR(_xlfn.XLOOKUP(F13,Lookup_Tables!Product,Cost),0) -> 22152 | Q13: =O13-P13 -> -20610.3 | R13: =Q13/O13 -> -13.368554
A14: ORD0013 | B14: 45423 | C14: West | D14: MH | E14: Karan | F14: Chair | G14: =INDEX(Lookup_Tables!$B$1:$B$7,MATCH(Cleaned_Data!F14,Lookup_Tables!$A$1:$A$7,0)) -> Furniture | H14: Furniture | I14: 9 | J14: 28406 | K14: 0.1 | L14: =IF(ISBLANK(K14),0,K14) -> 0.1 | N14: =I14*J14 -> 255654 | O14: =N14-(N14*L14) -> 230088.6 | P14: =I14*IFERROR(_xlfn.XLOOKUP(F14,Lookup_Tables!Product,Cost),0) -> 119439 | Q14: =O14-P14 -> 110649.6 | R14: =Q14/O14 -> 0.48089997
A15: ORD0014 | B15: 45400 | C15: North | D15: GJ | E15: Neha | F15: Laptop | G15: =INDEX(Lookup_Tables!$B$1:$B$7,MATCH(Cleaned_Data!F15,Lookup_Tables!$A$1:$A$7,0)) -> Electronics | H15: Electronics | I15: 6 | J15: 39809 | L15: =IF(ISBLANK(K15),0,K15) -> 0 | M15: 7704 | N15: =I15*J15 -> 238854 | O15: =N15-(N15*L15) -> 238854 | P15: =I15*IFERROR(_xlfn.XLOOKUP(F15,Lookup_Tables!Product,Cost),0) -> 115590 | Q15: =O15-P15 -> 123264 | R15: =Q15/O15 -> 0.51606421
A16: ORD0015 | B16: 45549 | C16: East | D16: GJ | E16: Karan | F16: Chair | G16: =INDEX(Lookup_Tables!$B$1:$B$7,MATCH(Cleaned_Data!F16,Lookup_Tables!$A$1:$A$7,0)) -> Furniture | H16: Furniture | I16: 3 | J16: 17089 | K16: 0.05 | L16: =IF(ISBLANK(K16),0,K16) -> 0.05 | N16: =I16*J16 -> 51267 | O16: =N16-(N16*L16) -> 48703.65 | P16: =I16*IFERROR(_xlfn.XLOOKUP(F16,Lookup_Tables!Product,Cost),0) -> 39813 | Q16: =O16-P16 -> 8890.65 | R16: =Q16/O16 -> 0.18254587
A17: ORD0016 | B17: 45401 | C17: East | D17: RJ | E17: Priya | F17: Monitor | G17: =INDEX(Lookup_Tables!$B$1:$B$7,MATCH(Cleaned_Data!F17,Lookup_Tables!$A$1:$A$7,0)) -> Electronics | H17: Electronics | I17: 9 | J17: 24048 | K17: 0 | L17: =IF(ISBLANK(K17),0,K17) -> 0 | N17: =I17*J17 -> 216432 | O17: =N17-(N17*L17) -> 216432 | P17: =I17*IFERROR(_xlfn.XLOOKUP(F17,Lookup_Tables!Product,Cost),0) -> 25992 | Q17: =O17-P17 -> 190440 | R17: =Q17/O17 -> 0.87990685
A18: ORD0017 | B18: 45342 | C18: North | D18: MH | E18: Neha | F18: Desk | G18: =INDEX(Lookup_Tables!$B$1:$B$7,MATCH(Cleaned_Data!F18,Lookup_Tables!$A$1:$A$7,0)) -> Furniture | H18: Furniture | I18: 6 | J18: 6121 | K18: 0 | L18: =IF(ISBLANK(K18),0,K18) -> 0 | M18: 8273 | N18: =I18*J18 -> 36726 | O18: =N18-(N18*L18) -> 36726 | P18: =I18*IFERROR(_xlfn.XLOOKUP(F18,Lookup_Tables!Product,Cost),0) -> 78240 | Q18: =O18-P18 -> -41514 | R18: =Q18/O18 -> -1.1303709
A19: ORD0018 | B19: 45388 | C19: North | D19: DL | E19: Neha | F19: Laptop | G19: =INDEX(Lookup_Tables!$B$1:$B$7,MATCH(Cleaned_Data!F19,Lookup_Tables!$A$1:$A$7,0)) -> Electronics | H19: Electronics | I19: 8 | J19: 29203 | K19: 0.05 | L19: =IF(ISBLANK(K19),0,K19) -> 0.05 | N19: =I19*J19 -> 233624 | O19: =N19-(N19*L19) -> 221942.8 | P19: =I19*IFERROR(_xlfn.XLOOKUP(F19,Lookup_Tables!Product,Cost),0) -> 154120 | Q19: =O19-P19 -> 67822.8 | R19: =Q19/O19 -> 0.30558684
A20: ORD0019 | B20: 45570 | C20: East | D20: GJ | E20: Neha | F20: Printer | G20: =INDEX(Lookup_Tables!$B$1:$B$7,MATCH(Cleaned_Data!F20,Lookup_Tables!$A$1:$A$7,0)) -> Electronics | H20: Electronics | I20: 6 | J20: 25953 | L20: =IF(ISBLANK(K20),0,K20) -> 0 | N20: =I20*J20 -> 155718 | O20: =N20-(N20*L20) -> 155718 | P20: =I20*IFERROR(_xlfn.XLOOKUP(F20,Lookup_Tables!Product,Cost),0) -> 44304 | Q20: =O20-P20 -> 111414 | R20: =Q20/O20 -> 0.71548569
A21: ORD0020 | B21: 45412 | C21: North | D21: GJ | E21: Karan | F21: Chair | G21: =INDEX(Lookup_Tables!$B$1:$B$7,MATCH(Cleaned_Data!F21,Lookup_Tables!$A$1:$A$7,0)) -> Furniture | H21: Furniture | I21: 9 | J21: 38450 | K21: 0 | L21: =IF(ISBLANK(K21),0,K21) -> 0 | N21: =I21*J21 -> 346050 | O21: =N21-(N21*L21) -> 346050 | P21: =I21*IFERROR(_xlfn.XLOOKUP(F21,Lookup_Tables!Product,Cost),0) -> 119439 | Q21: =O21-P21 -> 226611 | R21: =Q21/O21 -> 0.65485046
A22: ORD0021 | B22: 45626 | C22: West | D22: GJ | E22: Neha | F22: Printer | G22: =INDEX(Lookup_Tables!$B$1:$B$7,MATCH(Cleaned_Data!F22,Lookup_Tables!$A$1:$A$7,0)) -> Electronics | H22: Electronics | I22: 10 | J22: 14948 | K22: 0.05 | L22: =IF(ISBLANK(K22),0,K22) -> 0.05 | M22: 29773 | N22: =I22*J22 -> 149480 | O22: =N22-(N22*L22) -> 142006 | P22: =I22*IFERROR(_xlfn.XLOOKUP(F22,Lookup_Tables!Product,Cost),0) -> 73840 | Q22: =O22-P22 -> 68166 | R22: =Q22/O22 -> 0.48002197
A23: ORD0022 | B23: 45491 | C23: West | D23: DL | E23: Rahul | F23: Desk | G23: =INDEX(Lookup_Tables!$B$1:$B$7,MATCH(Cleaned_Data!F23,Lookup_Tables!$A$1:$A$7,0)) -> Furniture | H23: Furniture | I23: 10 | J23: 11429 | K23: 0.05 | L23: =IF(ISBLANK(K23),0,K23) -> 0.05 | N23: =I23*J23 -> 114290 | O23: =N23-(N23*L23) -> 108575.5 | P23: =I23*IFERROR(_xlfn.XLOOKUP(F23,Lookup_Tables!Product,Cost),0) -> 130400 | Q23: =O23-P23 -> -21824.5 | R23: =Q23/O23 -> -0.20100759
A24: ORD0023 | B24: 45479 | C24: East | D24: DL | E24: Priya | F24: Mouse | G24: =INDEX(Lookup_Tables!$B$1:$B$7,MATCH(Cleaned_Data!F24,Lookup_Tables!$A$1:$A$7,0)) -> Electronics | H24: Electronics | I24: 5 | J24: 11682 | K24: 0.1 | L24: =IF(ISBLANK(K24),0,K24) -> 0.1 | N24: =I24*J24 -> 58410 | O24: =N24-(N24*L24) -> 52569 | P24: =I24*IFERROR(_xlfn.XLOOKUP(F24,Lookup_Tables!Product,Cost),0) -> 140230 | Q24: =O24-P24 -> -87661 | R24: =Q24/O24 -> -1.6675417
A25: ORD0024 | B25: 45415 | C25: West | D25: MH | E25: Karan | F25: Printer | G25: =INDEX(Lookup_Tables!$B$1:$B$7,MATCH(Cleaned_Data!F25,Lookup_Tables!$A$1:$A$7,0)) -> Electronics | H25: Electronics | I25: 1 | J25: 43628 | K25: 0.05 | L25: =IF(ISBLANK(K25),0,K25) -> 0.05 | N25: =I25*J25 -> 43628 | O25: =N25-(N25*L25) -> 41446.6 | P25: =I25*IFERROR(_xlfn.XLOOKUP(F25,Lookup_Tables!Product,Cost),0) -> 7384 | Q25: =O25-P25 -> 34062.6 | R25: =Q25/O25 -> 0.82184305
A26: ORD0025 | B26: 45349 | C26: West | D26: TN | E26: Neha | F26: Monitor | G26: =INDEX(Lookup_Tables!$B$1:$B$7,MATCH(Cleaned_Data!F26,Lookup_Tables!$A$1:$A$7,0)) -> Electronics | H26: Electronics | I26: 2 | J26: 49900 | K26: 0 | L26: =IF(ISBLANK(K26),0,K26) -> 0 | N26: =I26*J26 -> 99800 | O26: =N26-(N26*L26) -> 99800 | P26: =I26*IFERROR(_xlfn.XLOOKUP(F26,Lookup_Tables!Product,Cost),0) -> 5776 | Q26: =O26-P26 -> 94024 | R26: =Q26/O26 -> 0.94212425
A27: ORD0026 | B27: 45618 | C27: East | D27: GJ | E27: Amit | F27: Desk | G27: =INDEX(Lookup_Tables!$B$1:$B$7,MATCH(Cleaned_Data!F27,Lookup_Tables!$A$1:$A$7,0)) -> Furniture | H27: Furniture | I27: 9 | J27: 25307 | L27: =IF(ISBLANK(K27),0,K27) -> 0 | M27: 7356 | N27: =I27*J27 -> 227763 | O27: =N27-(N27*L27) -> 227763 | P27: =I27*IFERROR(_xlfn.XLOOKUP(F27,Lookup_Tables!Product,Cost),0) -> 117360 | Q27: =O27-P27 -> 110403 | R27: =Q27/O27 -> 0.48472755
A28: ORD0027 | B28: 45655 | C28: East | D28: RJ | E28: Rahul | F28: Monitor | G28: =INDEX(Lookup_Tables!$B$1:$B$7,MATCH(Cleaned_Data!F28,Lookup_Tables!$A$1:$A$7,0)) -> Electronics | H28: Electronics | I28: 9 | J28: 47015 | K28: 0 | L28: =IF(ISBLANK(K28),0,K28) -> 0 | M28: 27705 | N28: =I28*J28 -> 423135 | O28: =N28-(N28*L28) -> 423135 | P28: =I28*IFERROR(_xlfn.XLOOKUP(F28,Lookup_Tables!Product,Cost),0) -> 25992 | Q28: =O28-P28 -> 397143 | R28: =Q28/O28 -> 0.9385728
A29: ORD0028 | B29: 45638 | C29: East | D29: RJ | E29: Neha | F29: Monitor | G29: =INDEX(Lookup_Tables!$B$1:$B$7,MATCH(Cleaned_Data!F29,Lookup_Tables!$A$1:$A$7,0)) -> Electronics | H29: Electronics | I29: 4 | J29: 34893 | K29: 0.1 | L29: =IF(ISBLANK(K29),0,K29) -> 0.1 | N29: =I29*J29 -> 139572 | O29: =N29-(N29*L29) -> 125614.8 | P29: =I29*IFERROR(_xlfn.XLOOKUP(F29,Lookup_Tables!Product,Cost),0) -> 11552 | Q29: =O29-P29 -> 114062.8 | R29: =Q29/O29 -> 0.90803631
A30: ORD0029 | B30: 45315 | C30: South | D30: DL | E30: Amit | F30: Chair | G30: =INDEX(Lookup_Tables!$B$1:$B$7,MATCH(Cleaned_Data!F30,Lookup_Tables!$A$1:$A$7,0)) -> Furniture | H30: Furniture | I30: 9 | J30: 26283 | L30: =IF(ISBLANK(K30),0,K30) -> 0 | N30: =I30*J30 -> 236547 | O30: =N30-(N30*L30) -> 236547 | P30: =I30*IFERROR(_xlfn.XLOOKUP(F30,Lookup_Tables!Product,Cost),0) -> 119439 | Q30: =O30-P30 -> 117108 | R30: =Q30/O30 -> 0.49507286
A31: ORD0030 | B31: 45544 | C31: South | D31: TN | E31: Amit | F31: Laptop | G31: =INDEX(Lookup_Tables!$B$1:$B$7,MATCH(Cleaned_Data!F31,Lookup_Tables!$A$1:$A$7,0)) -> Electronics | H31: Electronics | I31: 2 | J31: 26513 | K31: 0.1 | L31: =IF(ISBLANK(K31),0,K31) -> 0.1 | N31: =I31*J31 -> 53026 | O31: =N31-(N31*L31) -> 47723.4 | P31: =I31*IFERROR(_xlfn.XLOOKUP(F31,Lookup_Tables!Product,Cost),0) -> 38530 | Q31: =O31-P31 -> 9193.4 | R31: =Q31/O31 -> 0.19263925
A32: ORD0031 | B32: 45529 | C32: North | D32: GJ | E32: Amit | F32: Laptop | G32: =INDEX(Lookup_Tables!$B$1:$B$7,MATCH(Cleaned_Data!F32,Lookup_Tables!$A$1:$A$7,0)) -> Electronics | H32: Electronics | I32: 9 | J32: 49552 | K32: 0.1 | L32: =IF(ISBLANK(K32),0,K32) -> 0.1 | M32: 22087 | N32: =I32*J32 -> 445968 | O32: =N32-(N32*L32) -> 401371.2 | P32: =I32*IFERROR(_xlfn.XLOOKUP(F32,Lookup_Tables!Product,Cost),0) -> 173385 | Q32: =O32-P32 -> 227986.2 | R32: =Q32/O32 -> 0.56801833
A33: ORD0032 | B33: 45479 | C33: North | D33: DL | E33: Karan | F33: Monitor | G33: =INDEX(Lookup_Tables!$B$1:$B$7,MATCH(Cleaned_Data!F33,Lookup_Tables!$A$1:$A$7,0)) -> Electronics | H33: Electronics | I33: 6 | J33: 26441 | L33: =IF(ISBLANK(K33),0,K33) -> 0 | M33: 21986 | N33: =I33*J33 -> 158646 | O33: =N33-(N33*L33) -> 158646 | P33: =I33*IFERROR(_xlfn.XLOOKUP(F33,Lookup_Tables!Product,Cost),0) -> 17328 | Q33: =O33-P33 -> 141318 | R33: =Q33/O33 -> 0.89077569
A34: ORD0033 | B34: 45561 | C34: South | D34: RJ | E34: Rahul | F34: Printer | G34: =INDEX(Lookup_Tables!$B$1:$B$7,MATCH(Cleaned_Data!F34,Lookup_Tables!$A$1:$A$7,0)) -> Electronics | H34: Electronics | I34: 9 | J34: 30588 | K34: 0.1 | L34: =IF(ISBLANK(K34),0,K34) -> 0.1 | M34: 22011 | N34: =I34*J34 -> 275292 | O34: =N34-(N34*L34) -> 247762.8 | P34: =I34*IFERROR(_xlfn.XLOOKUP(F34,Lookup_Tables!Product,Cost),0) -> 66456 | Q34: =O34-P34 -> 181306.8 | R34: =Q34/O34 -> 0.73177571
A35: ORD0034 | B35: 45336 | C35: West | D35: TN | E35: Rahul | F35: Monitor | G35: =INDEX(Lookup_Tables!$B$1:$B$7,MATCH(Cleaned_Data!F35,Lookup_Tables!$A$1:$A$7,0)) -> Electronics | H35: Electronics | I35: 9 | J35: 27695 | L35: =IF(ISBLANK(K35),0,K35) -> 0 | N35: =I35*J35 -> 249255 | O35: =N35-(N35*L35) -> 249255 | P35: =I35*IFERROR(_xlfn.XLOOKUP(F35,Lookup_Tables!Product,Cost),0) -> 25992 | Q35: =O35-P35 -> 223263 | R35: =Q35/O35 -> 0.89572125
A36: ORD0035 | B36: 45642 | C36: West | D36: MH | E36: Karan | F36: Printer | G36: =INDEX(Lookup_Tables!$B$1:$B$7,MATCH(Cleaned_Data!F36,Lookup_Tables!$A$1:$A$7,0)) -> Electronics | H36: Electronics | I36: 2 | J36: 10738 | K36: 0 | L36: =IF(ISBLANK(K36),0,K36) -> 0 | M36: 5576 | N36: =I36*J36 -> 21476 | O36: =N36-(N36*L36) -> 21476 | P36: =I36*IFERROR(_xlfn.XLOOKUP(F36,Lookup_Tables!Product,Cost),0) -> 14768 | Q36: =O36-P36 -> 6708 | R36: =Q36/O36 -> 0.31234867
A37: ORD0036 | B37: 45336 | C37: West | D37: MH | E37: Rahul | F37: Monitor | G37: =INDEX(Lookup_Tables!$B$1:$B$7,MATCH(Cleaned_Data!F37,Lookup_Tables!$A$1:$A$7,0)) -> Electronics | H37: Electronics | I37: 6 | J37: 7619 | L37: =IF(ISBLANK(K37),0,K37) -> 0 | M37: 13277 | N37: =I37*J37 -> 45714 | O37: =N37-(N37*L37) -> 45714 | P37: =I37*IFERROR(_xlfn.XLOOKUP(F37,Lookup_Tables!Product,Cost),0) -> 17328 | Q37: =O37-P37 -> 28386 | R37: =Q37/O37 -> 0.62094763
A38: ORD0037 | B38: 45346 | C38: West | D38: GJ | E38: Neha | F38: Laptop | G38: =INDEX(Lookup_Tables!$B$1:$B$7,MATCH(Cleaned_Data!F38,Lookup_Tables!$A$1:$A$7,0)) -> Electronics | H38: Electronics | I38: 8 | J38: 37570 | L38: =IF(ISBLANK(K38),0,K38) -> 0 | N38: =I38*J38 -> 300560 | O38: =N38-(N38*L38) -> 300560 | P38: =I38*IFERROR(_xlfn.XLOOKUP(F38,Lookup_Tables!Product,Cost),0) -> 154120 | Q38: =O38-P38 -> 146440 | R38: =Q38/O38 -> 0.48722385
A39: ORD0038 | B39: 45560 | C39: East | D39: GJ | E39: Neha | F39: Printer | G39: =INDEX(Lookup_Tables!$B$1:$B$7,MATCH(Cleaned_Data!F39,Lookup_Tables!$A$1:$A$7,0)) -> Electronics | H39: Electronics | I39: 1 | J39: 12074 | K39: 0.1 | L39: =IF(ISBLANK(K39),0,K39) -> 0.1 | N39: =I39*J39 -> 12074 | O39: =N39-(N39*L39) -> 10866.6 | P39: =I39*IFERROR(_xlfn.XLOOKUP(F39,Lookup_Tables!Product,Cost),0) -> 7384 | Q39: =O39-P39 -> 3482.6 | R39: =Q39/O39 -> 0.32048663
A40: ORD0039 | B40: 45397 | C40: South | D40: TN | E40: Priya | F40: Printer | G40: =INDEX(Lookup_Tables!$B$1:$B$7,MATCH(Cleaned_Data!F40,Lookup_Tables!$A$1:$A$7,0)) -> Electronics | H40: Electronics | I40: 1 | J40: 44737 | K40: 0.1 | L40: =IF(ISBLANK(K40),0,K40) -> 0.1 | M40: 24975 | N40: =I40*J40 -> 44737 | O40: =N40-(N40*L40) -> 40263.3 | P40: =I40*IFERROR(_xlfn.XLOOKUP(F40,Lookup_Tables!Product,Cost),0) -> 7384 | Q40: =O40-P40 -> 32879.3 | R40: =Q40/O40 -> 0.81660718
...

Sheet Raw_Data
A1: Order ID | B1: Order Date | C1: Region | D1: State | E1: Salesperson | F1: Product | G1: Category | H1: Quantity | I1: Unit Price | J1: Discount | K1: Cost Price
A2: ORD0001 | B2: 45503 | C2: East | D2: MH | E2: Rahul | F2: Chair | G2: Furniture | H2: 8 | I2: 25761 | J2: 0.05 | K2: 29955
A3: ORD0002 | B3: 45527 | C3: West | D3: RJ | E3: Neha | F3: Laptop | G3: Electronics | H3: 3 | I3: 21400 | K3: 6742
A4: ORD0003 | B4: 45624 | C4: East | D4: GJ | E4: Karan | F4: Laptop | G4: Electronics | H4: 6 | I4: 40298
A5: ORD0004 | B5: 45311 | C5: North | D5: MH | E5: Rahul | F5: Monitor | G5: Electronics | H5: 9 | I5: 1098 | K5: 7334
A6: ORD0005 | B6: 45632 | C6: West | D6: RJ | E6: Karan | F6: Chair | G6: Furniture | H6: 4 | I6: 15968
A7: ORD0006 | B7: 45339 | C7: West | D7: RJ | E7: Amit | F7: Printer | G7: Electronics | H7: 10 | I7: 36961 | J7: 0.05 | K7: 16608
A8: ORD0007 | B8: 45618 | C8: North | D8: MH | E8: Amit | F8: Monitor | G8: Electronics | H8: 3 | I8: 1683 | K8: 25507
A9: ORD0008 | B9: 45476 | C9: South | D9: KA | E9: Amit | F9: Printer | G9: Electronics | H9: 2 | I9: 6047 | J9: 0.05
A10: ORD0009 | B10: 45530 | C10: North | D10: MH | E10: Amit | F10: Mouse | G10: Electronics | H10: 2 | I10: 3101 | J10: 0.1 | K10: 23538
A11: ORD0010 | B11: 45413 | C11: West | D11: MH | E11: Neha | F11: Printer | G11: Electronics | H11: 8 | I11: 41602 | J11: 0 | K11: 29885
A12: ORD0011 | B12: 45649 | C12: West | D12: GJ | E12: Karan | F12: Laptop | G12: Electronics | H12: 2 | I12: 17931 | J12: 0.1
A13: ORD0012 | B13: 45443 | C13: West | D13: TN | E13: Rahul | F13: Printer | G13: Electronics | H13: 3 | I13: 571 | J13: 0.1
A14: ORD0013 | B14: 45423 | C14: West | D14: MH | E14: Karan | F14: Chair | G14: Furniture | H14: 9 | I14: 28406 | J14: 0.1
A15: ORD0014 | B15: 45400 | C15: North | D15: GJ | E15: Neha | F15: Laptop | G15: Electronics | H15: 6 | I15: 39809 | K15: 7704
A16: ORD0015 | B16: 45549 | C16: East | D16: GJ | E16: Karan | F16: Chair | G16: Furniture | H16: 3 | I16: 17089 | J16: 0.05
A17: ORD0016 | B17: 45401 | C17: East | D17: RJ | E17: Priya | F17: Monitor | G17: Electronics | H17: 9 | I17: 24048 | J17: 0
A18: ORD0017 | B18: 45342 | C18: North | D18: MH | E18: Neha | F18: Desk | G18: Furniture | H18: 6 | I18: 6121 | J18: 0 | K18: 8273
A19: ORD0018 | B19: 45388 | C19: North | D19: DL | E19: Neha | F19: Laptop | G19: Electronics | H19: 8 | I19: 29203 | J19: 0.05
A20: ORD0019 | B20: 45570 | C20: East | D20: GJ | E20: Neha | F20: Printer | G20: Electronics | H20: 6 | I20: 25953
A21: ORD0020 | B21: 45412 | C21: North | D21: GJ | E21: Karan | F21: Chair | G21: Furniture | H21: 9 | I21: 38450 | J21: 0
A22: ORD0021 | B22: 45626 | C22: West | D22: GJ | E22: Neha | F22: Printer | G22: Electronics | H22: 10 | I22: 14948 | J22: 0.05 | K22: 29773
A23: ORD0022 | B23: 45491 | C23: West | D23: DL | E23: Rahul | F23: Desk | G23: Furniture | H23: 10 | I23: 11429 | J23: 0.05
A24: ORD0023 | B24: 45479 | C24: East | D24: DL | E24: Priya | F24: Mouse | G24: Electronics | H24: 5 | I24: 11682 | J24: 0.1
A25: ORD0024 | B25: 45415 | C25: West | D25: MH | E25: Karan | F25: Printer | G25: Electronics | H25: 1 | I25: 43628 | J25: 0.05
A26: ORD0025 | B26: 45349 | C26: West | D26: TN | E26: Neha | F26: Monitor | G26: Electronics | H26: 2 | I26: 49900 | J26: 0
A27: ORD0026 | B27: 45618 | C27: East | D27: GJ | E27: Amit | F27: Desk | G27: Furniture | H27: 9 | I27: 25307 | K27: 7356
A28: ORD0027 | B28: 45655 | C28: East | D28: RJ | E28: Rahul | F28: Monitor | G28: Electronics | H28: 9 | I28: 47015 | J28: 0 | K28: 27705
A29: ORD0028 | B29: 45638 | C29: East | D29: RJ | E29: Neha | F29: Monitor | G29: Electronics | H29: 4 | I29: 34893 | J29: 0.1
A30: ORD0029 | B30: 45315 | C30: South | D30: DL | E30: Amit | F30: Chair | G30: Furniture | H30: 9 | I30: 26283
A31: ORD0030 | B31: 45544 | C31: South | D31: TN | E31: Amit | F31: Laptop | G31: Electronics | H31: 2 | I31: 26513 | J31: 0.1
A32: ORD0031 | B32: 45529 | C32: North | D32: GJ | E32: Amit | F32: Laptop | G32: Electronics | H32: 9 | I32: 49552 | J32: 0.1 | K32: 22087
A33: ORD0032 | B33: 45479 | C33: North | D33: DL | E33: Karan | F33: Monitor | G33: Electronics | H33: 6 | I33: 26441 | K33: 21986
A34: ORD0033 | B34: 45561 | C34: South | D34: RJ | E34: Rahul | F34: Printer | G34: Electronics | H34: 9 | I34: 30588 | J34: 0.1 | K34: 22011
A35: ORD0034 | B35: 45336 | C35: West | D35: TN | E35: Rahul | F35: Monitor | G35: Electronics | H35: 9 | I35: 27695
A36: ORD0035 | B36: 45642 | C36: West | D36: MH | E36: Karan | F36: Printer | G36: Electronics | H36: 2 | I36: 10738 | J36: 0 | K36: 5576
A37: ORD0036 | B37: 45336 | C37: West | D37: MH | E37: Rahul | F37: Monitor | G37: Electronics | H37: 6 | I37: 7619 | K37: 13277
A38: ORD0037 | B38: 45346 | C38: West | D38: GJ | E38: Neha | F38: Laptop | G38: Electronics | H38: 8 | I38: 37570
A39: ORD0038 | B39: 45560 | C39: East | D39: GJ | E39: Neha | F39: Printer | G39: Electronics | H39: 1 | I39: 12074 | J39: 0.1
A40: ORD0039 | B40: 45397 | C40: South | D40: TN | E40: Priya | F40: Printer | G40: Electronics | H40: 1 | I40: 44737 | J40: 0.1 | K40: 24975
...

Sheet Lookup_Tables
A1: Product | B1: Category | C1: Cost
A2: Laptop | B2: Electronics | C2: 19265
A3: Mouse | B3: Electronics | C3: 28046
A4: Chair | B4: Furniture | C4: 13271
A5: Desk | B5: Furniture | C5: 13040
A6: Printer | B6: Electronics | C6: 7384
A7: Monitor | B7: Electronics | C7: 2888
A9: Region | B9: Target
A10: North | B10: 484968
A11: South | B11: 302462
A12: East | B12: 574404
A13: West | B13: 539344
